from auto_process import catch_toError


print(catch_toError('1546'))